Workbook

Sheet EDT
A1: EDT - Estructura de Descomposición del Trabajo: FireFleet
A2: Sistema de Control y Seguimiento de Mantención de Vehículos de Emergencia · Cuerpo de Bomberos de Talcahuano · Capstone 002D
A3: Fuente de actividades y días: Carta Gantt del proyecto (días hábiles). Horas = Días × horas de dedicación diaria por integrante asignado.
J4: Horas de dedicación por día | M4: 3
A6: ID | B6: Actividad / Entregable | C6: Días | D6: SM | E6: DW | F6: DM | G6: Total HH | H6: Costo ($) | I6: Grupo | J6: SIGLA | K6: ROL | L6: NOMBRE | M6: COSTO x HORA
A7: 1 | B7: Fase 1: Definición del proyecto | J7: SM | K7: Scrum Master / Analista | L7: Álvaro Caroca | M7: ='ANALISIS INGRESOS'!$G$6 -> 10833.333
A8: 1.1 | B8: Definición del proyecto y levantamiento inicial | C8: 2 | D8: =C8*$M$4 -> 6 | E8: =C8*$M$4 -> 6 | F8: =C8*$M$4 -> 6 | G8: =SUM(D8:F8) -> 18 | H8: =D8*'ANALISIS INGRESOS'!$G$6+E8*'ANALISIS INGRESOS'!$G$9+F8*'ANALISIS INGRESOS'!$G$8 -> 103333.33 | I8: F1 | J8: DW | K8: Desarrollador web, backend y BD | L8: Emmanuel Cabrera | M8: ='ANALISIS INGRESOS'!$G$9 -> 3611.1111
A9: 1.2 | B9: Entrevista con Bomberos y análisis AS-IS | C9: 2 | D9: =C9*$M$4 -> 6 | E9: =C9*$M$4 -> 6 | F9: =C9*$M$4 -> 6 | G9: =SUM(D9:F9) -> 18 | H9: =D9*'ANALISIS INGRESOS'!$G$6+E9*'ANALISIS INGRESOS'!$G$9+F9*'ANALISIS INGRESOS'!$G$8 -> 103333.33 | I9: F1 | J9: DM | K9: Desarrollador móvil (Android) | L9: Felipe Castañeda | M9: ='ANALISIS INGRESOS'!$G$8 -> 2777.7778
A10: 1.3 | B10: Redacción: descripción, competencias, intereses y factibilidad | C10: 3 | D10: =C10*$M$4 -> 9 | E10: =C10*$M$4 -> 9 | F10: =C10*$M$4 -> 9 | G10: =SUM(D10:F10) -> 27 | H10: =D10*'ANALISIS INGRESOS'!$G$6+E10*'ANALISIS INGRESOS'!$G$9+F10*'ANALISIS INGRESOS'!$G$8 -> 155000 | I10: F1 | J10: PO | K10: Product Owner | L10: Juan Andrés Hernández Aliaga | M10: Sin costo (docente)
A11: 1.4 | B11: Objetivos y metodología | C11: 2 | D11: =C11*$M$4 -> 6 | E11: =C11*$M$4 -> 6 | F11: =C11*$M$4 -> 6 | G11: =SUM(D11:F11) -> 18 | H11: =D11*'ANALISIS INGRESOS'!$G$6+E11*'ANALISIS INGRESOS'!$G$9+F11*'ANALISIS INGRESOS'!$G$8 -> 103333.33 | I11: F1 | J11: Tarifas: hoja ANALISIS INGRESOS (SM = Jefe de Proyecto, DW = Desarrollador BD, DM = Programador).
A12: 1.5 | B12: Plan de trabajo y Carta Gantt | C12: 2 | D12: =C12*$M$4 -> 6 | G12: =SUM(D12:F12) -> 6 | H12: =D12*'ANALISIS INGRESOS'!$G$6+E12*'ANALISIS INGRESOS'!$G$9+F12*'ANALISIS INGRESOS'!$G$8 -> 65000 | I12: F1
A13: 1.6 | B13: Consolidación del informe EV_1 y evidencias | C13: 2 | D13: =C13*$M$4 -> 6 | E13: =C13*$M$4 -> 6 | F13: =C13*$M$4 -> 6 | G13: =SUM(D13:F13) -> 18 | H13: =D13*'ANALISIS INGRESOS'!$G$6+E13*'ANALISIS INGRESOS'!$G$9+F13*'ANALISIS INGRESOS'!$G$8 -> 103333.33 | I13: F1 | J13: COSTO POR FASE | M13: Costo ($)
A14: 1.7 | B14: Hito 1: Entrega y presentación EVA 1 | C14: 0 | G14: =SUM(D14:F14) -> 0 | H14: =D14*'ANALISIS INGRESOS'!$G$6+E14*'ANALISIS INGRESOS'!$G$9+F14*'ANALISIS INGRESOS'!$G$8 -> 0 | I14: F1 | J14: Fase 1: Definición del proyecto | M14: =SUMIF($I$7:$I$70,"F1",$H$7:$H$70) -> 633333.33
A15: 2 | B15: Fase 2: Levantamiento, Product Backlog y arquitectura | J15: Fase 2: Levantamiento y arquitectura | M15: =SUMIF($I$7:$I$70,"F2",$H$7:$H$70) -> 537500
A16: 2.1 | B16: Mapeo de actores y visión | C16: 2 | D16: =C16*$M$4 -> 6 | G16: =SUM(D16:F16) -> 6 | H16: =D16*'ANALISIS INGRESOS'!$G$6+E16*'ANALISIS INGRESOS'!$G$9+F16*'ANALISIS INGRESOS'!$G$8 -> 65000 | I16: F2 | J16: Fase 3: Desarrollo (Sprints 0 a 5) | M16: =SUMIF($I$7:$I$70,"S0",$H$7:$H$70)+SUMIF($I$7:$I$70,"S1",$H$7:$H$70)+SUMIF($I$7:$I$70,"S2",$H$7:$H$70)+SUMIF($I$7:$I$70,"S3",$H$7:$H$70)+SUMIF($I$7:$I$70,"S4",$H$7:$H$70)+SUMIF($I$7:$I$70,"S5",$H$7:$H$70) -> 1430000
A17: 2.2 | B17: Épicas e historias de usuario | C17: 3 | D17: =C17*$M$4 -> 9 | E17: =C17*$M$4 -> 9 | F17: =C17*$M$4 -> 9 | G17: =SUM(D17:F17) -> 27 | H17: =D17*'ANALISIS INGRESOS'!$G$6+E17*'ANALISIS INGRESOS'!$G$9+F17*'ANALISIS INGRESOS'!$G$8 -> 155000 | I17: F2 | J17: Fase 4: Integración, validación y cierre | M17: =SUMIF($I$7:$I$70,"F4",$H$7:$H$70) -> 225833.33
A18: 2.3 | B18: User Story Mapping y definición de releases | C18: 2 | D18: =C18*$M$4 -> 6 | G18: =SUM(D18:F18) -> 6 | H18: =D18*'ANALISIS INGRESOS'!$G$6+E18*'ANALISIS INGRESOS'!$G$9+F18*'ANALISIS INGRESOS'!$G$8 -> 65000 | I18: F2 | J18: Fase 5: Presentación final | M18: =SUMIF($I$7:$I$70,"F5",$H$7:$H$70) -> 258333.33
A19: 2.4 | B19: Product Backlog priorizado | C19: 3 | D19: =C19*$M$4 -> 9 | G19: =SUM(D19:F19) -> 9 | H19: =D19*'ANALISIS INGRESOS'!$G$6+E19*'ANALISIS INGRESOS'!$G$9+F19*'ANALISIS INGRESOS'!$G$8 -> 97500 | I19: F2 | J19: TOTAL PROYECTO | M19: =SUM(M14:M18) -> 3085000
A20: 2.5 | B20: Diseño de arquitectura (DAS, vistas 4+1) | C20: 3 | D20: =C20*$M$4 -> 9 | E20: =C20*$M$4 -> 9 | F20: =C20*$M$4 -> 9 | G20: =SUM(D20:F20) -> 27 | H20: =D20*'ANALISIS INGRESOS'!$G$6+E20*'ANALISIS INGRESOS'!$G$9+F20*'ANALISIS INGRESOS'!$G$8 -> 155000 | I20: F2 | J20: Control (debe ser igual al total de la columna H) | M20: =H71 -> 3085000
A21: 3 | B21: Fase 3: Desarrollo (Scrum)
A22: 3.1 | B22: Sprint 0: Configuración base | J22: COSTO POR SPRINT | K22: HH | L22: Estado (11-10-2026) | M22: Costo ($)
A23: 3.1.1 | B23: Sprint Planning | C23: 1 | D23: =C23*$M$4 -> 3 | E23: =C23*$M$4 -> 3 | F23: =C23*$M$4 -> 3 | G23: =SUM(D23:F23) -> 9 | H23: =D23*'ANALISIS INGRESOS'!$G$6+E23*'ANALISIS INGRESOS'!$G$9+F23*'ANALISIS INGRESOS'!$G$8 -> 51666.667 | I23: S0 | J23: Sprint 0 | K23: =SUMIF($I$7:$I$70,"S0",$G$7:$G$70) -> 27 | L23: Terminado | M23: =SUMIF($I$7:$I$70,"S0",$H$7:$H$70) -> 111666.67
A24: 3.1.2 | B24: Configuración de repositorio GitHub y entorno Django + SQLite | C24: 2 | E24: =C24*$M$4 -> 6 | F24: =C24*$M$4 -> 6 | G24: =SUM(D24:F24) -> 12 | H24: =D24*'ANALISIS INGRESOS'!$G$6+E24*'ANALISIS INGRESOS'!$G$9+F24*'ANALISIS INGRESOS'!$G$8 -> 38333.333 | I24: S0 | J24: Sprint 1 | K24: =SUMIF($I$7:$I$70,"S1",$G$7:$G$70) -> 48 | L24: Terminado | M24: =SUMIF($I$7:$I$70,"S1",$H$7:$H$70) -> 230833.33
A25: 3.1.3 | B25: Diseño e implementación inicial del modelo de datos | C25: 2 | E25: =C25*$M$4 -> 6 | G25: =SUM(D25:F25) -> 6 | H25: =D25*'ANALISIS INGRESOS'!$G$6+E25*'ANALISIS INGRESOS'!$G$9+F25*'ANALISIS INGRESOS'!$G$8 -> 21666.667 | I25: S0 | J25: Sprint 2 | K25: =SUMIF($I$7:$I$70,"S2",$G$7:$G$70) -> 60 | L25: En curso | M25: =SUMIF($I$7:$I$70,"S2",$H$7:$H$70) -> 247500
A26: 3.1.4 | B26: Hito 2: Entorno y modelo de datos configurados | C26: 0 | G26: =SUM(D26:F26) -> 0 | H26: =D26*'ANALISIS INGRESOS'!$G$6+E26*'ANALISIS INGRESOS'!$G$9+F26*'ANALISIS INGRESOS'!$G$8 -> 0 | I26: S0 | J26: Sprint 3 | K26: =SUMIF($I$7:$I$70,"S3",$G$7:$G$70) -> 54 | L26: Planificado | M26: =SUMIF($I$7:$I$70,"S3",$H$7:$H$70) -> 242500
A27: 3.2 | B27: Sprint 1: Registro y estado de vehículos | J27: Sprint 4 | K27: =SUMIF($I$7:$I$70,"S4",$G$7:$G$70) -> 81 | L27: Planificado | M27: =SUMIF($I$7:$I$70,"S4",$H$7:$H$70) -> 327500
A28: 3.2.1 | B28: Sprint Planning | C28: 1 | D28: =C28*$M$4 -> 3 | E28: =C28*$M$4 -> 3 | F28: =C28*$M$4 -> 3 | G28: =SUM(D28:F28) -> 9 | H28: =D28*'ANALISIS INGRESOS'!$G$6+E28*'ANALISIS INGRESOS'!$G$9+F28*'ANALISIS INGRESOS'!$G$8 -> 51666.667 | I28: S1 | J28: Sprint 5 | K28: =SUMIF($I$7:$I$70,"S5",$G$7:$G$70) -> 63 | L28: Planificado | M28: =SUMIF($I$7:$I$70,"S5",$H$7:$H$70) -> 270000
A29: 3.2.2 | B29: Backend: módulo Vehículos e inicio de sesión | C29: 4 | E29: =C29*$M$4 -> 12 | G29: =SUM(D29:F29) -> 12 | H29: =D29*'ANALISIS INGRESOS'!$G$6+E29*'ANALISIS INGRESOS'!$G$9+F29*'ANALISIS INGRESOS'!$G$8 -> 43333.333 | I29: S1
A30: 3.2.3 | B30: Frontend web: ficha y estado del vehículo | C30: 3 | E30: =C30*$M$4 -> 9 | G30: =SUM(D30:F30) -> 9 | H30: =D30*'ANALISIS INGRESOS'!$G$6+E30*'ANALISIS INGRESOS'!$G$9+F30*'ANALISIS INGRESOS'!$G$8 -> 32500 | I30: S1 | J30: COSTO HH POR ROL | K30: HH | M30: Costo ($)
A31: 3.2.4 | B31: Sprint Review y Retrospective | C31: 2 | D31: =C31*$M$4 -> 6 | E31: =C31*$M$4 -> 6 | F31: =C31*$M$4 -> 6 | G31: =SUM(D31:F31) -> 18 | H31: =D31*'ANALISIS INGRESOS'!$G$6+E31*'ANALISIS INGRESOS'!$G$9+F31*'ANALISIS INGRESOS'!$G$8 -> 103333.33 | I31: S1 | J31: SM · Álvaro Caroca | K31: =D71 -> 150 | M31: =D71*'ANALISIS INGRESOS'!$G$6 -> 1625000
A32: 3.2.5 | B32: Hito 3: Módulo Vehículos operativo | C32: 0 | G32: =SUM(D32:F32) -> 0 | H32: =D32*'ANALISIS INGRESOS'!$G$6+E32*'ANALISIS INGRESOS'!$G$9+F32*'ANALISIS INGRESOS'!$G$8 -> 0 | I32: S1 | J32: DW · Emmanuel Cabrera | K32: =E71 -> 252 | M32: =E71*'ANALISIS INGRESOS'!$G$9 -> 910000
A33: 3.3 | B33: Sprint 2: Gestión de mantenciones | J33: DM · Felipe Castañeda | K33: =F71 -> 198 | M33: =F71*'ANALISIS INGRESOS'!$G$8 -> 550000
A34: 3.3.1 | B34: Sprint Planning | C34: 1 | D34: =C34*$M$4 -> 3 | E34: =C34*$M$4 -> 3 | F34: =C34*$M$4 -> 3 | G34: =SUM(D34:F34) -> 9 | H34: =D34*'ANALISIS INGRESOS'!$G$6+E34*'ANALISIS INGRESOS'!$G$9+F34*'ANALISIS INGRESOS'!$G$8 -> 51666.667 | I34: S2 | J34: TOTAL HH | K34: =SUM(K31:K33) -> 600 | M34: =SUM(M31:M33) -> 3085000
A35: 3.3.2 | B35: Backend: mantenciones, insumos y costos | C35: 5 | E35: =C35*$M$4 -> 15 | G35: =SUM(D35:F35) -> 15 | H35: =D35*'ANALISIS INGRESOS'!$G$6+E35*'ANALISIS INGRESOS'!$G$9+F35*'ANALISIS INGRESOS'!$G$8 -> 54166.667 | I35: S2
A36: 3.3.3 | B36: Frontend web: registro de mantenciones e historial | C36: 3 | E36: =C36*$M$4 -> 9 | G36: =SUM(D36:F36) -> 9 | H36: =D36*'ANALISIS INGRESOS'!$G$6+E36*'ANALISIS INGRESOS'!$G$9+F36*'ANALISIS INGRESOS'!$G$8 -> 32500 | I36: S2 | J36: Nota: costo referencial de mercado para dimensionar el esfuerzo. El proyecto académico no tiene costo real (restricción Presupuesto $0 del DAS).
A37: 3.3.4 | B37: Alertas de mantención por vencer y vencidas | C37: 3 | E37: =C37*$M$4 -> 9 | F37: =C37*$M$4 -> 9 | G37: =SUM(D37:F37) -> 18 | H37: =D37*'ANALISIS INGRESOS'!$G$6+E37*'ANALISIS INGRESOS'!$G$9+F37*'ANALISIS INGRESOS'!$G$8 -> 57500 | I37: S2
A38: 3.3.5 | B38: Sprint Review y Retrospective | C38: 1 | D38: =C38*$M$4 -> 3 | E38: =C38*$M$4 -> 3 | F38: =C38*$M$4 -> 3 | G38: =SUM(D38:F38) -> 9 | H38: =D38*'ANALISIS INGRESOS'!$G$6+E38*'ANALISIS INGRESOS'!$G$9+F38*'ANALISIS INGRESOS'!$G$8 -> 51666.667 | I38: S2
A39: 3.3.6 | B39: Hito 4: Módulo Mantenciones operativo | C39: 0 | G39: =SUM(D39:F39) -> 0 | H39: =D39*'ANALISIS INGRESOS'!$G$6+E39*'ANALISIS INGRESOS'!$G$9+F39*'ANALISIS INGRESOS'!$G$8 -> 0 | I39: S2
A40: 3.4 | B40: Sprint 3: App móvil y disponibilidad del carro
A41: 3.4.1 | B41: Sprint Planning | C41: 1 | D41: =C41*$M$4 -> 3 | E41: =C41*$M$4 -> 3 | F41: =C41*$M$4 -> 3 | G41: =SUM(D41:F41) -> 9 | H41: =D41*'ANALISIS INGRESOS'!$G$6+E41*'ANALISIS INGRESOS'!$G$9+F41*'ANALISIS INGRESOS'!$G$8 -> 51666.667 | I41: S3
...

Sheet ANALISIS INGRESOS
H2: FUENTE DE INFORMACION www.mifuturo.cl / www.universia.cl
H3: INGENIERIA INFORMÁTICA
C4: EXPERIENCIA
A5: SIGLA | B5: ROL | C5: (- 2 años) | D5: (+2 años) | E5: RESPONS. | F5: SUELDO | G5: HH
A6: JP | B6: Jefe de Proyecto | D6: x | E6: 0.5 | F6: =(C20*E6)+1300000 -> 1950000 | G6: =F6/180 -> 10833.333
A7: AF | B7: Analista Funcional | D7: x | E7: 0.3 | F7: =(C22*E7)+1300000 -> 1300000 | G7: =F7/180 -> 7222.2222
A8: PG | B8: Programador | C8: x | F8: =B19 -> 500000 | G8: =F8/180 -> 2777.7778
A9: DBA | B9: Desarrollador BD | C9: x | E9: 0.3 | F9: =(B19*E9)+500000 -> 650000 | G9: =F9/180 -> 3611.1111
A10: TS | B10: Testing | C10: x | F10: =B19 -> 500000 | G10: =F10/180 -> 2777.7778
A11: DI | B11: Diseñador | C11: x | F11: 500000 | G11: =F11/180 -> 2777.7778
D14: Hrs.Sem. | E14: 45
D15: HRS.Mens. | E15: =E14*4 -> 180
D16: HH | E16: Sueldo/180hrs
A18: PROMEDIO | B18: PROGRAMADOR | C18: INGENIERO | D18: DISEÑADOR
A19: Ingreso Primer Año | B19: 500000 | C19: 700000 | D19: 500000
A20: Ingreso Experiencia | B20: 900000 | C20: 1300000 | D20: 800000
H23: ANALISTA PROGRAMADOR
H42: DISEÑADOR
